Workbook

Sheet 總名冊
A1: 桃 | B1: 舍 | C1: 姓 | D1: 房 | E1: 型 | F1: 房號 | G1: 床 | H1: 學號 | I1: 班級 | J1: 姓名 | K1: 電話 | L1: 修業 | M1: 國籍 | N1: 學籍 | O1: 身分 | P1: 註2
A2: 桃 | B2: 德明 | C2: 男 | D2: 套 | E2: 3 | F2: 1231 | G2: A | H2: 特殊 | J2: 特殊
A3: 桃 | B3: 德明 | C3: 男 | D3: 套 | E3: 3 | F3: 1231 | G3: B | H3: 12130340 | I3: 資管三甲 | J3: 林煜晟 | K3: 0952367130 | L3: 4年 | M3: 台灣 | N3: 學位生 | O3: 本地生
A4: 桃 | B4: 德明 | C4: 男 | D4: 套 | E4: 3 | F4: 1231 | G4: C | H4: 特殊 | J4: 特殊
A5: 桃 | B5: 德明 | C5: 男 | D5: 套 | E5: 3 | F5: 1251 | G5: A | H5: 12050696 | I5: 電機三乙 | J5: 蔡承佑 | K5: 0902159795 | L5: 4年 | M5: 台灣 | N5: 學位生 | O5: 本地生
A6: 桃 | B6: 德明 | C6: 男 | D6: 套 | E6: 3 | F6: 1251 | G6: B | H6: 12050804 | I6: 電機三乙 | J6: 黃晨洲 | K6: 0977376556 | L6: 4年 | M6: 台灣 | N6: 學位生 | O6: 本地生
A7: 桃 | B7: 德明 | C7: 男 | D7: 套 | E7: 3 | F7: 1251 | G7: C | H7: 特殊 | J7: 特殊
A8: 桃 | B8: 德明 | C8: 男 | D8: 套 | E8: 3 | F8: 0972 | G8: A | H8: 12130055 | I8: 資管三甲 | J8: 張宸愷 | K8: 0909977931 | L8: 4年 | M8: 台灣 | N8: 學位生 | O8: 本地生
A9: 桃 | B9: 德明 | C9: 男 | D9: 套 | E9: 3 | F9: 0972 | G9: B | H9: 12130463 | I9: 資管三甲 | J9: 陳樂奇 | K9: 0968967928 | L9: 4年 | M9: 台灣 | N9: 學位生 | O9: 本地生
A10: 桃 | B10: 德明 | C10: 男 | D10: 套 | E10: 3 | F10: 0972 | G10: C | H10: 12131555 | I10: 資管三甲 | J10: 何易昕 | K10: 0979515600 | L10: 4年 | M10: 台灣 | N10: 學位生 | O10: 本地生
A11: 桃 | B11: 德明 | C11: 男 | D11: 套 | E11: 3 | F11: 0992 | G11: A | H11: 14230090 | I11: 品設一甲 | J11: 蘇煒翔 | K11: 0926155933 | L11: 4年 | M11: 台灣 | N11: 學位生 | O11: 本地生
A12: 桃 | B12: 德明 | C12: 男 | D12: 套 | E12: 3 | F12: 0992 | G12: B | H12: 14131092 | I12: 資管一丙 | J12: 林鈺博 | K12: 0965821700 | L12: 4年 | M12: 台灣 | N12: 學位生 | O12: 本地生
A13: 桃 | B13: 德明 | C13: 男 | D13: 套 | E13: 3 | F13: 0992 | G13: C | H13: 14130274 | I13: 資管一甲 | J13: 郭廷祐 | K13: 0905530261 | L13: 4年 | M13: 台灣 | N13: 學位生 | O13: 本地生
A14: 桃 | B14: 德明 | C14: 男 | D14: 套 | E14: 3 | F14: 1012 | G14: A | H14: 特殊 | J14: 健管室
A15: 桃 | B15: 德明 | C15: 男 | D15: 套 | E15: 3 | F15: 1012 | G15: B | H15: 特殊 | J15: 健管室
A16: 桃 | B16: 德明 | C16: 男 | D16: 套 | E16: 3 | F16: 1012 | G16: C | H16: 特殊 | J16: 健管室
A17: 桃 | B17: 德明 | C17: 男 | D17: 套 | E17: 3 | F17: 1032 | G17: A | H17: 14361465 | I17: 資工一甲 | J17: 王秉淳 | K17: 0909423307 | L17: 4年 | M17: 台灣 | N17: 學位生 | O17: 本地生
A18: 桃 | B18: 德明 | C18: 男 | D18: 套 | E18: 3 | F18: 1032 | G18: B | H18: 14190963 | I18: 餐旅一甲 | J18: 鍾智峰 | L18: 4年 | M18: 巴西 | N18: 學位生 | O18: 僑生 | P18: 僑生
A19: 桃 | B19: 德明 | C19: 男 | D19: 套 | E19: 3 | F19: 1032 | G19: C | H19: 14360170 | I19: 資工一甲 | J19: 楊宇紘 | K19: 0982761549 | L19: 4年 | M19: 台灣 | N19: 學位生 | O19: 本地生 | P19: 0958362322
A20: 桃 | B20: 德明 | C20: 男 | D20: 套 | E20: 3 | F20: 1052 | G20: A | H20: 14360223 | I20: 資工一甲 | J20: 馬弘儒 | K20: 0958667735 | L20: 4年 | M20: 台灣 | N20: 學位生 | O20: 本地生
A21: 桃 | B21: 德明 | C21: 男 | D21: 套 | E21: 3 | F21: 1052 | G21: B | H21: 11130970 | I21: 資管四甲 | J21: 徐靖儒 | K21: 0981152073 | L21: 4年 | M21: 台灣 | N21: 學位生 | O21: 本地生
A22: 桃 | B22: 德明 | C22: 男 | D22: 套 | E22: 3 | F22: 1052 | G22: C | H22: 14140340 | I22: 觀光一甲 | J22: 許竣輔 | K22: 0983515185 | L22: 4年 | M22: 台灣 | N22: 學位生 | O22: 本地生
A23: 桃 | B23: 德明 | C23: 男 | D23: 套 | E23: 3 | F23: 1072 | G23: A | H23: 14390336 | I23: 生科一甲 | J23: 陳奕棋 | K23: 0910261771 | L23: 4年 | M23: 台灣 | N23: 學位生 | O23: 本地生 | P23: 0921224240
A24: 桃 | B24: 德明 | C24: 男 | D24: 套 | E24: 3 | F24: 1072 | G24: B | H24: 14180295 | I24: 休憩一甲 | J24: 吳承啟 | K24: 0900774689 | L24: 4年 | M24: 台灣 | N24: 學位生 | O24: 本地生 | P24: 0937166392
A25: 桃 | B25: 德明 | C25: 男 | D25: 套 | E25: 3 | F25: 1072 | G25: C | H25: 12140023 | I25: 觀光三甲 | J25: 郭昱暐 | K25: 0917877829 | L25: 4年 | M25: 台灣 | N25: 學位生 | O25: 本地生
A26: 桃 | B26: 德明 | C26: 男 | D26: 套 | E26: 3 | F26: 1092 | G26: A | H26: 14180261 | I26: 休憩一甲 | J26: 蕭亦綸 | K26: 0909788996 | L26: 4年 | M26: 台灣 | N26: 學位生 | O26: 本地生 | P26: 0958712770
A27: 桃 | B27: 德明 | C27: 男 | D27: 套 | E27: 3 | F27: 1092 | G27: B | H27: 14180022 | I27: 休憩一甲 | J27: 李偉綸 | K27: 0981416091 | L27: 4年 | M27: 台灣 | N27: 學位生 | O27: 本地生 | P27: 087776475
A28: 桃 | B28: 德明 | C28: 男 | D28: 套 | E28: 3 | F28: 1092 | G28: C | H28: 14190192 | I28: 餐旅一甲 | J28: 吳建勳 | K28: 0981928128 | L28: 4年 | M28: 台灣 | N28: 學位生 | O28: 本地生 | P28: 0976383958
A29: 桃 | B29: 德明 | C29: 男 | D29: 套 | E29: 3 | F29: 1252 | G29: A | H29: 14686512 | I29: 公行研一 | J29: 石躍龍 | K29: 0989487034 | L29: 半年 | M29: 中國 | N29: 交換生 | O29: 國際生
A30: 桃 | B30: 德明 | C30: 男 | D30: 套 | E30: 3 | F30: 1252 | G30: B | H30: 14642016 | I30: 金融三甲 | J30: 尹秋池 | L30: 半年 | M30: 中國 | N30: 交換生 | O30: 國際生
A31: 桃 | B31: 德明 | C31: 男 | D31: 套 | E31: 3 | F31: 1252 | G31: C | H31: 14142020 | I31: 觀光三甲 | J31: 桑翌晨 | K31: 0965433980 | L31: 半年 | M31: 中國 | N31: 交換生 | O31: 國際生
A32: 桃 | B32: 德明 | C32: 男 | D32: 套 | E32: 3 | F32: 1272 | G32: A | H32: 12500096 | I32: 數媒三丁 | J32: 趙宇晟 | K32: 0908503217 | L32: 4年 | M32: 台灣 | N32: 學位生 | O32: 本地生
A33: 桃 | B33: 德明 | C33: 男 | D33: 套 | E33: 3 | F33: 1272 | G33: B | H33: 14442014 | I33: 應日四甲 | J33: 賈延琦 | K33: 0965433860 | L33: 半年 | M33: 中國 | N33: 交流生 | O33: 國際生
A34: 桃 | B34: 德明 | C34: 男 | D34: 套 | E34: 3 | F34: 1272 | G34: C | H34: 13240422 | I34: 建築二甲 | J34: 周凡恩 | K34: 0932940510 | L34: 4年 | M34: 台灣 | N34: 學位生 | O34: 本地生
A35: 桃 | B35: 德明 | C35: 男 | D35: 套 | E35: 3 | F35: 1292 | G35: A | H35: 14142045 | I35: 觀光三甲 | J35: 白浩宇 | K35: 0965433948 | L35: 半年 | M35: 中國 | N35: 交換生 | O35: 國際生
A36: 桃 | B36: 德明 | C36: 男 | D36: 套 | E36: 3 | F36: 1292 | G36: B | H36: 14142054 | I36: 觀光三甲 | J36: 郭宇翔 | K36: 0965433935 | L36: 半年 | M36: 中國 | N36: 交流生 | O36: 國際生
A37: 桃 | B37: 德明 | C37: 男 | D37: 套 | E37: 3 | F37: 1292 | G37: C | H37: 14142063 | I37: 觀光三甲 | J37: 盧建華 | K37: 0965433922 | L37: 半年 | M37: 中國 | N37: 交流生 | O37: 國際生
A38: 桃 | B38: 德明 | C38: 男 | D38: 套 | E38: 3 | F38: 1312 | G38: A | H38: 14842011 | I38: 電機三甲 | J38: 李智銳 | K38: 0983449057 | L38: 半年 | M38: 中國 | N38: 交流生 | O38: 國際生
A39: 桃 | B39: 德明 | C39: 男 | D39: 套 | E39: 3 | F39: 1312 | G39: B | H39: 14092013 | I39: 數媒二甲 | J39: 傅貞豪 | K39: 0965434639 | L39: 半年 | M39: 中國 | N39: 交流生 | O39: 國際生
A40: 桃 | B40: 德明 | C40: 男 | D40: 套 | E40: 3 | F40: 1312 | G40: C | H40: 14092022 | I40: 數媒二甲 | J40: 李宇君 | K40: 0965434631 | L40: 半年 | M40: 中國 | N40: 交流生 | O40: 國際生
...

Sheet 男生(2)
A1: 銘傳大學德明宿舍查鋪記錄表男 2F
A2: 二樓 | B2: 床號 | C2: 姓 名 | D2: 班 級 | E2: 日 | F2: 一 | G2: 二 | H2: 三 | I2: 四 | J2: 二樓 | K2: 床號 | L2: 姓 名 | M2: 班 級 | N2: 日 | O2: 一 | P2: 二 | Q2: 三 | R2: 四
A4: 97 | B4: A | C4: =T(總名冊!J8) -> 張宸愷 | D4: =T(總名冊!I8) -> 資管三甲 | J4: 125 | K4: A | L4: =T(總名冊!J29) -> 石躍龍 | M4: =T(總名冊!I29) -> 公行研一
B5: B | C5: =T(總名冊!J9) -> 陳樂奇 | D5: =T(總名冊!I9) -> 資管三甲 | K5: B | L5: =T(總名冊!J30) -> 尹秋池 | M5: =T(總名冊!I30) -> 金融三甲
B6: C | C6: =T(總名冊!J10) -> 何易昕 | D6: =T(總名冊!I10) -> 資管三甲 | K6: C | L6: =T(總名冊!J31) -> 桑翌晨 | M6: =T(總名冊!I31) -> 觀光三甲
A7: 99 | B7: A | C7: =T(總名冊!J11) -> 蘇煒翔 | D7: =T(總名冊!I11) -> 品設一甲 | J7: 127 | K7: A | L7: =T(總名冊!J158) -> NGUYEN PHU THINH | M7: =T(總名冊!I158) -> 資訊學程一
B8: B | C8: =T(總名冊!J12) -> 林鈺博 | D8: =T(總名冊!I12) -> 資管一丙 | K8: B | L8: =T(總名冊!J134) -> 村田瑛斗 | M8: =T(總名冊!I134) -> 應日研一
B9: C | C9: =T(總名冊!J13) -> 郭廷祐 | D9: =T(總名冊!I13) -> 資管一甲 | K9: C | L9: =T(總名冊!J34) -> 周凡恩 | M9: =T(總名冊!I34) -> 建築二甲
A10: 101 | B10: A | C10: =T(總名冊!J14) -> 健管室 | D10: =T(總名冊!I14) | J10: 129 | K10: A | L10: =T(總名冊!J35) -> 白浩宇 | M10: =T(總名冊!I35) -> 觀光三甲
B11: B | C11: =T(總名冊!J15) -> 健管室 | D11: =T(總名冊!I15) | K11: B | L11: =T(總名冊!J135) -> 蘇杰 | M11: =T(總名冊!I135) -> 外交學程一
B12: C | C12: =T(總名冊!J16) -> 健管室 | D12: =T(總名冊!I16) | K12: C | L12: =T(總名冊!J37) -> 盧建華 | M12: =T(總名冊!I37) -> 觀光三甲
A13: 103 | B13: A | C13: =T(總名冊!J17) -> 王秉淳 | D13: =T(總名冊!I17) -> 資工一甲 | J13: 131 | K13: A | L13: =T(總名冊!J38) -> 李智銳 | M13: =T(總名冊!I38) -> 電機三甲
B14: B | C14: =T(總名冊!J18) -> 鍾智峰 | D14: =T(總名冊!I18) -> 餐旅一甲 | K14: B | L14: =T(總名冊!J39) -> 傅貞豪 | M14: =T(總名冊!I39) -> 數媒二甲
B15: C | C15: =T(總名冊!J19) -> 楊宇紘 | D15: =T(總名冊!I19) -> 資工一甲 | K15: C | L15: =T(總名冊!J40) -> 李宇君 | M15: =T(總名冊!I40) -> 數媒二甲
A16: 105 | B16: A | C16: =T(總名冊!J20) -> 馬弘儒 | D16: =T(總名冊!I20) -> 資工一甲 | J16: 133 | K16: A | L16: =T(總名冊!J41) -> 李坤隆 | M16: =T(總名冊!I41) -> 資管三乙
B17: B | C17: =T(總名冊!J21) -> 徐靖儒 | D17: =T(總名冊!I21) -> 資管四甲 | K17: B | L17: =T(總名冊!J42) -> 林皇觀 | M17: =T(總名冊!I42) -> 醫工一甲
B18: C | C18: =T(總名冊!J247) -> 王俊霖 | D18: =T(總名冊!I247) -> 電機二丁 | K18: C | L18: =T(總名冊!#REF!) -> #REF! | M18: =T(總名冊!#REF!) -> #REF!
A19: 107 | B19: A | C19: =T(總名冊!J23) -> 陳奕棋 | D19: =T(總名冊!I23) -> 生科一甲 | J19: 135 | K19: A | L19: =T(總名冊!#REF!) -> #REF! | M19: =T(總名冊!#REF!) -> #REF!
B20: B | C20: =T(總名冊!J24) -> 吳承啟 | D20: =T(總名冊!I24) -> 休憩一甲 | K20: B | L20: =T(總名冊!J43) -> 高健熙 | M20: =T(總名冊!I43) -> 醫管一甲
B21: C | C21: =T(總名冊!J25) -> 郭昱暐 | D21: =T(總名冊!I25) -> 觀光三甲 | K21: C | L21: =T(總名冊!J44) -> 俞競航 | M21: =T(總名冊!I44) -> 數媒二甲
A22: 109 | B22: A | C22: =T(總名冊!J26) -> 蕭亦綸 | D22: =T(總名冊!I26) -> 休憩一甲 | J22: 137 | K22: A | L22: =T(總名冊!J45) -> 張海波 | M22: =T(總名冊!I45) -> 數媒二甲
B23: B | C23: =T(總名冊!J27) -> 李偉綸 | D23: =T(總名冊!I27) -> 休憩一甲 | K23: B | L23: =T(總名冊!J46) -> 熊 輝 | M23: =T(總名冊!I46) -> 數媒二甲
B24: C | C24: =T(總名冊!J28) -> 吳建勳 | D24: =T(總名冊!I28) -> 餐旅一甲 | K24: C | L24: =T(總名冊!#REF!) -> #REF! | M24: =T(總名冊!#REF!) -> #REF!

Sheet 男生(3)
A1: 銘傳大學德明宿舍查鋪記錄表男 3F
A2: 三樓 | B2: 床號 | C2: 姓 名 | D2: 班 級 | E2: 日 | F2: 一 | G2: 二 | H2: 三 | I2: 四 | J2: 三樓 | K2: 床號 | L2: 姓 名 | M2: 班 級 | N2: 日 | O2: 一 | P2: 二 | Q2: 三 | R2: 四
A4: 97 | B4: A | C4: =T(總名冊!J48) -> 林健楷 | D4: =T(總名冊!I48) -> 商設二乙 | J4: 125 | K4: A | L4: =T(總名冊!J69) -> 劉得均 | M4: =T(總名冊!I69) -> 商設一乙
B5: B | C5: =T(總名冊!J49) -> 王威勝 | D5: =T(總名冊!I49) -> 心理一乙 | K5: B | L5: =T(總名冊!J70) -> 吳佑嘉 | M5: =T(總名冊!I70) -> 品設一乙
B6: C | C6: =T(總名冊!J50) -> 蘇昱銘 | D6: =T(總名冊!I50) -> 人智一乙 | K6: C | L6: =T(總名冊!J71) -> 麥張彥朋 | M6: =T(總名冊!I71) -> 電機一甲
A7: 99 | B7: A | C7: =T(總名冊!J51) -> 張子坤 | D7: =T(總名冊!I51) -> 電機四丁 | J7: 127 | K7: A | L7: =T(總名冊!J72) -> 江聖頎 | M7: =T(總名冊!I72) -> 電機一丙
B8: B | C8: =T(總名冊!J52) -> 廖宜莛 | D8: =T(總名冊!I52) -> 半導體一甲 | K8: B | L8: =T(總名冊!J73) -> 陳心颺 | M8: =T(總名冊!I73) -> 電機二丁
B9: C | C9: =T(總名冊!J53) -> 蔡明宏 | D9: =T(總名冊!I53) -> 數媒一甲 | K9: C | L9: =T(總名冊!J74) -> 許閎凱 | M9: =T(總名冊!I74) -> 電機一乙
A10: 101 | B10: A | C10: =T(總名冊!J54) -> 王嵩哲 | D10: =T(總名冊!I54) -> 數媒一乙 | J10: 129 | K10: A | L10: =T(總名冊!J75) -> 蔣昕和 | M10: =T(總名冊!I75) -> 半導體一甲
B11: B | C11: =T(總名冊!J55) -> 陳怡憲 | D11: =T(總名冊!I55) -> 數媒一乙 | K11: B | L11: =T(總名冊!J76) -> 周韋志 | M11: =T(總名冊!I76) -> 電機一乙
B12: C | C12: =T(總名冊!J56) -> 徐良祁 | D12: =T(總名冊!I56) -> 資管二丙 | K12: C | L12: =T(總名冊!J77) -> 林佑丞 | M12: =T(總名冊!I77) -> 犯防一乙
A13: 103 | B13: A | C13: =T(總名冊!J57) -> 江臣俊 | D13: =T(總名冊!I57) -> 餐旅四甲 | J13: 131 | K13: A | L13: =T(總名冊!J78) -> 劉宥均 | M13: =T(總名冊!I78) -> 犯防一乙
B14: B | C14: =T(總名冊!J58) -> 黃鉦文 | D14: =T(總名冊!I58) -> 文華一甲 | K14: B | L14: =T(總名冊!J79) -> 董恩睿 | M14: =T(總名冊!I79) -> 犯防一甲
B15: C | C15: =T(總名冊!J59) -> 黃孜鼎 | D15: =T(總名冊!I59) -> 數媒一乙 | K15: C | L15: =T(總名冊!J80) -> 葉仲詠 | M15: =T(總名冊!I80) -> 金融二甲
A16: 105 | B16: A | C16: =T(總名冊!J60) -> 曾梓祐 | D16: =T(總名冊!I60) -> 建築一甲 | J16: 133 | K16: A | L16: =T(總名冊!J81) -> 楊宗晏 | M16: =T(總名冊!I81) -> 電機一甲
B17: B | C17: =T(總名冊!#REF!) -> #REF! | D17: =T(總名冊!#REF!) -> #REF! | K17: B | L17: =T(總名冊!J82) -> 謝浚宏 | M17: =T(總名冊!I82) -> 電機一丙
B18: C | C18: =T(總名冊!J62) -> 馮建鈞 | D18: =T(總名冊!I62) -> 應日三乙 | K18: C | L18: =T(總名冊!J83) -> 楊宗祐 | M18: =T(總名冊!I83) -> 觀光四甲
A19: 107 | B19: A | C19: =T(總名冊!J63) -> 林柏瀚 | D19: =T(總名冊!I63) -> 應日四乙 | J19: 135 | K19: A | L19: =T(總名冊!J84) -> 賴宇哲 | M19: =T(總名冊!I84) -> 電機一甲
B20: B | C20: =T(總名冊!J64) -> 廖昱翔 | D20: =T(總名冊!I64) -> 應日三甲 | K20: B | L20: =T(總名冊!J85) -> 鄭皓勻 | M20: =T(總名冊!I85) -> 金科一甲
B21: C | C21: =T(總名冊!J65) -> 吳承峰 | D21: =T(總名冊!I65) -> 應日二甲 | K21: C | L21: =T(總名冊!J86) -> 張容福 | M21: =T(總名冊!I86) -> 資管三乙
A22: 109 | B22: A | C22: =T(總名冊!J66) -> 林文勗 | D22: =T(總名冊!I66) -> 應日一甲 | J22: 137 | K22: A | L22: =T(總名冊!J87) -> 王廉程 | M22: =T(總名冊!I87) -> 資管三丙
B23: B | C23: =T(總名冊!J67) -> 彭新凱 | D23: =T(總名冊!I67) -> 商設一乙 | K23: B | L23: =T(總名冊!#REF!) -> #REF! | M23: =T(總名冊!J95) -> 黃星維
B24: C | C24: =T(總名冊!J68) -> 高擷凱 | D24: =T(總名冊!I68) -> 商設一甲 | K24: C | L24: =T(總名冊!J89) -> 陳致璿 | M24: =T(總名冊!I89) -> 資管一丙

Sheet 男生(4)
A1: 銘傳大學德明宿舍查鋪記錄表男 4F
A2: 四樓 | B2: 床號 | C2: 姓 名 | D2: 班 級 | E2: 日 | F2: 一 | G2: 二 | H2: 三 | I2: 四 | J2: 四樓 | K2: 床號 | L2: 姓 名 | M2: 班 級 | N2: 日 | O2: 一 | P2: 二 | Q2: 三 | R2: 四
A4: 97 | B4: A | C4: =T(總名冊!J90) -> 邱繼緯 | D4: =T(總名冊!I90) -> 資管一丙 | J4: 125 | K4: A | L4: =T(總名冊!J111) -> 裴孟林 | M4: =T(總名冊!I111) -> 餐旅系
B5: B | C5: =T(總名冊!J91) -> 陳立恩 | D5: =T(總名冊!I91) -> 資管一丙 | K5: B | L5: =T(總名冊!J61) -> 吳一君 | M5: =T(總名冊!I61) -> 建築一甲
B6: C | C6: =T(總名冊!J92) -> 黃柏瑜 | D6: =T(總名冊!I92) -> 資管一甲 | K6: C | L6: =T(總名冊!J113) -> 張秦瑜 | M6: =T(總名冊!I113) -> 資工一丙
A7: 99 | B7: A | C7: =T(總名冊!J93) -> 阮梓睿 | D7: =T(總名冊!I93) -> 資管一丙 | J7: 127 | K7: A | L7: =T(總名冊!J114) -> 蔡幸霖 | M7: =T(總名冊!I114) -> 資工一甲
B8: B | C8: =T(總名冊!J94) -> 蔡承洋 | D8: =T(總名冊!I94) -> 人智一乙 | K8: B | L8: =T(總名冊!J115) -> 徐澤亞 | M8: =T(總名冊!I115) -> 觀光一甲
B9: C | C9: =T(總名冊!#REF!) -> #REF! | D9: =T(總名冊!#REF!) -> #REF! | K9: C | L9: =T(總名冊!J116) -> 鄭凱瑞 | M9: =T(總名冊!I116) -> 餐旅一甲
A10: 101 | B10: A | C10: =T(總名冊!J96) -> 賴禹丞 | D10: =T(總名冊!I96) -> 應英一甲 | J10: 129 | K10: A | L10: =T(總名冊!J117) -> 胡振雍 | M10: =T(總名冊!I117) -> 生科一乙
B11: B | C11: =T(總名冊!J97) -> 洪睿廷 | D11: =T(總名冊!I97) -> 金融一甲 | K11: B | L11: =T(總名冊!J118) -> 盧劭齊 | M11: =T(總名冊!I118) -> 生科一乙
B12: C | C12: =T(總名冊!J98) -> 沈奕呈 | D12: =T(總名冊!I98) -> 資管一甲 | K12: C | L12: =T(總名冊!J119) -> 範世英 | M12: =T(總名冊!I119) -> 資工系
A13: 103 | B13: A | C13: =T(總名冊!J99) -> 張鈞皓 | D13: =T(總名冊!I99) -> 資工一乙 | J13: 131 | K13: A | L13: =T(總名冊!J120) -> 阮俊傑 | M13: =T(總名冊!I120) -> 資工系
B14: B | C14: =T(總名冊!J100) -> 蔡侑勳 | D14: =T(總名冊!I100) -> 生科一甲 | K14: B | L14: =T(總名冊!J121) -> 陳明芳 | M14: =T(總名冊!I121) -> 資工系
B15: C | C15: =T(總名冊!J160) -> Mzwandile Brian Mavuso | D15: =T(總名冊!I160) -> 外交學程一 | K15: C | L15: =T(總名冊!J122) -> 陳清純 | M15: =T(總名冊!I122) -> 觀光系
A16: 105 | B16: A | C16: =T(總名冊!J102) -> DANG THANH SON | D16: =T(總名冊!I102) -> 觀光學程三 | J16: 133 | K16: A | L16: =T(總名冊!J123) -> 陳光榮 | M16: =T(總名冊!I123) -> 觀光系
B17: B | C17: =T(總名冊!J101) -> BUI AN DUY | D17: =T(總名冊!I101) -> 半導體一乙 | K17: B | L17: =T(總名冊!J124) -> 武庭營 | M17: =T(總名冊!I124) -> 觀光系
B18: C | C18: =T(總名冊!J104) -> 鄧日新 | D18: =T(總名冊!I104) -> 資工系 | K18: C | L18: =T(總名冊!J125) -> 曾楷程 | M18: =T(總名冊!I125) -> 電機三丁
A19: 107 | B19: A | C19: =T(總名冊!J105) -> 范孟越 | D19: =T(總名冊!I105) -> 資工系 | J19: 135 | K19: A | L19: =T(總名冊!J126) -> 黃博楷 | M19: =T(總名冊!I126) -> 資訊學程四
B20: B | C20: =T(總名冊!J106) -> SANCHIR AMAR | D20: =T(總名冊!I106) -> 半導體一乙 | K20: B | L20: =T(總名冊!#REF!) -> #REF! | M20: =T(總名冊!#REF!) -> #REF!
B21: C | C21: =T(總名冊!J107) -> 范友榮 | D21: =T(總名冊!I107) -> 餐旅系 | K21: C | L21: =T(總名冊!J128) -> 葉俊佑 | M21: =T(總名冊!I128) -> 資工二丙
A22: 109 | B22: A | C22: =T(總名冊!J108) -> 阮玉卿 | D22: =T(總名冊!I108) -> 餐旅系 | J22: 137 | K22: A | L22: =T(總名冊!J129) -> 曾濬澤 | M22: =T(總名冊!I129) -> 金融一甲
B23: B | C23: =T(總名冊!J109) -> 阮懷安 | D23: =T(總名冊!I109) -> 餐旅系 | K23: B | L23: =T(總名冊!J130) -> 陳璽仲 | M23: =T(總名冊!I130) -> 電機二甲
B24: C | C24: =T(總名冊!J110) -> 鄧嘉輝 | D24: =T(總名冊!I110) -> 餐旅系 | K24: C | L24: =T(總名冊!J131) -> 武菲陽 | M24: =T(總名冊!I131) -> 資工系

Sheet 男生(5)
A1: 銘傳大學德明宿舍查鋪記錄表男 5F
A2: 五樓 | B2: 床號 | C2: 姓 名 | D2: 班 級 | E2: 日 | F2: 一 | G2: 二 | H2: 三 | I2: 四 | J2: 五樓 | K2: 床號 | L2: 姓 名 | M2: 班 級 | N2: 日 | O2: 一 | P2: 二 | Q2: 三 | R2: 四
A4: 97 | B4: A | C4: =T(總名冊!J132) -> 陳文決 | D4: =T(總名冊!I132) -> 都防系 | J4: 125 | K4: A | L4: =T(總名冊!J138) -> NGOC DUY | M4: =T(總名冊!I138) -> 資訊學程一
B5: B | C5: =T(總名冊!J133) -> 阮庭戰勝 | D5: =T(總名冊!I133) -> 資工系 | K5: B | L5: =T(總名冊!J154) -> 黃文豐 | M5: =T(總名冊!I154) -> 外交學程二
B6: C | C6: =T(總名冊!#REF!) -> #REF! | D6: =T(總名冊!#REF!) -> #REF! | K6: C | L6: =T(總名冊!J155) -> DO QUY VUONG | M6: =T(總名冊!I155) -> 觀光學程三
A7: 99 | B7: A | C7: =T(總名冊!#REF!) -> #REF! | D7: =T(總名冊!#REF!) -> #REF! | J7: 127 | K7: A | L7: =T(總名冊!J156) -> 范黃江 | M7: =T(總名冊!I156) -> 生科二丙
B8: B | C8: =T(總名冊!J136) -> 鈴木雄津人 | D8: =T(總名冊!I136) -> 外交學程三 | K8: B | L8: =T(總名冊!J157) -> 陳寶山 | M8: =T(總名冊!I157) -> 生科二丙
B9: C | C9: =T(總名冊!J137) -> DOAN THANH AN | D9: =T(總名冊!I137) -> 資訊學程一 | K9: C | L9: =T(總名冊!#REF!) -> #REF! | M9: =T(總名冊!#REF!) -> #REF!
A10: 101 | B10: A | C10: =T(總名冊!#REF!) -> #REF! | D10: =T(總名冊!#REF!) -> #REF! | J10: 129 | K10: A | L10: =T(總名冊!J159) -> TRAN HOANG DAT | M10: =T(總名冊!I159) -> 觀光學程三
B11: B | C11: =T(總名冊!J139) -> NGOC DUC THINH | D11: =T(總名冊!I139) -> 資訊學程一 | K11: B | L11: =T(總名冊!J103) -> PHAM VIET HUNG | M11: =T(總名冊!I103) -> 觀光學程三
B12: C | C12: =T(總名冊!J140) -> 武俊興 | D12: =T(總名冊!I140) -> 觀光學程四 | K12: C | L12: =T(總名冊!J161) -> ZUZILE LWAZI ANDREW | M12: =T(總名冊!I161) -> 資訊學程一
A13: 103 | B13: A | C13: =T(總名冊!J174) -> 宋家樑 | D13: =T(總名冊!I174) -> 醫管一甲 | J13: 131 | K13: A | L13: =T(總名冊!J162) -> SIMELANE KWANELE SISHOSONKE | M13: =T(總名冊!I162) -> 資訊學程一
B14: B | C14: =T(總名冊!J142) -> 阮世國寶 | D14: =T(總名冊!I142) -> 資訊學程二 | K14: B | L14: =T(總名冊!J163) -> 曾俊惟 | M14: =T(總名冊!I163) -> 休憩一甲
B15: C | C15: =T(總名冊!J143) -> 劉政澔 | D15: =T(總名冊!I143) -> 電機二甲 | K15: C | L15: =T(總名冊!J164) -> 翁晟泰 | M15: =T(總名冊!I164) -> 人智三乙
A16: 105 | B16: A | C16: =T(總名冊!J144) -> 陳泳宏 | D16: =T(總名冊!I144) -> 數媒一甲 | J16: 133 | K16: A | L16: =T(總名冊!J165) -> 劉祐任 | M16: =T(總名冊!I165) -> 數媒一甲
B17: B | C17: =T(總名冊!J145) -> 林哲維 | D17: =T(總名冊!I145) -> 資工碩二 | K17: B | L17: =T(總名冊!J166) -> 古承軒 | M17: =T(總名冊!I166) -> 電機三丁
B18: C | C18: =T(總名冊!J146) -> DINH TUAN ANH | D18: =T(總名冊!I146) -> 觀光學程三 | K18: C | L18: =T(總名冊!#REF!) -> #REF! | M18: =T(總名冊!#REF!) -> #REF!
A19: 107 | B19: A | C19: =T(總名冊!J147) -> NGUYEN TUAN ANH | D19: =T(總名冊!I147) -> 觀光學程三 | J19: 135 | K19: A | L19: =T(總名冊!#REF!) -> #REF! | M19: =T(總名冊!#REF!) -> #REF!
B20: B | C20: =T(總名冊!J148) -> NGUYEN MINH TRI | D20: =T(總名冊!I148) -> 觀光學程三 | K20: B | L20: =T(總名冊!J169) -> 森山聖矢 | M20: =T(總名冊!I169) -> 心理二乙
B21: C | C21: =T(總名冊!J149) -> 范明德 | D21: =T(總名冊!I149) -> 應英二甲 | K21: C | L21: =T(總名冊!J170) -> 曾永鈞 | M21: =T(總名冊!I170) -> 生科一乙
A22: 109 | B22: A | C22: =T(總名冊!J150) -> 阮慶林 | D22: =T(總名冊!I150) -> 生科二丙 | J22: 137 | K22: A | L22: =T(總名冊!J88) -> 李峻毅 | M22: =T(總名冊!I88) -> 金融一甲
B23: B | C23: =T(總名冊!J151) -> 黎聲河 | D23: =T(總名冊!I151) -> 生科二丙 | K23: B | L23: =T(總名冊!#REF!) -> #REF! | M23: =T(總名冊!#REF!) -> #REF!
B24: C | C24: =T(總名冊!J152) -> 許忠勝 | D24: =T(總名冊!I152) -> 資訊學程一 | K24: C | L24: =T(總名冊!J173) -> 周承威 | M24: =T(總名冊!I173) -> 醫管一甲

Sheet 女生(3)
A1: 銘傳大學德明宿舍查鋪記錄表女 3F
A2: 三樓 | B2: 床號 | C2: 姓 名 | D2: 班 級 | E2: 日 | F2: 一 | G2: 二 | H2: 三 | I2: 四 | J2: 三樓 | K2: 床號 | L2: 姓 名 | M2: 班 級 | N2: 日 | O2: 一 | P2: 二 | Q2: 三 | R2: 四
A4: 83 | B4: A | C4: =T(總名冊!#REF!) -> #REF! | D4: =T(總名冊!#REF!) -> #REF! | J4: 111 | K4: A | L4: =T(總名冊!J361) -> 蘇穎慧 | M4: =T(總名冊!I361) -> 心理諮商二
B5: B | C5: =T(總名冊!J341) -> 王淑華 | D5: =T(總名冊!I341) -> 大陸老師 | K5: B | L5: =T(總名冊!J362) -> 張恬萭 | M5: =T(總名冊!I362) -> 金融一甲
B6: C | C6: =T(總名冊!J342) -> 王淑華 | D6: =T(總名冊!I342) -> 大陸老師 | K6: C | L6: =T(總名冊!J363) -> 郭芯安 | M6: =T(總名冊!I363) -> 犯防二甲
A7: 85 | B7: A | C7: =T(總名冊!J343) -> 楊 豔 | D7: =T(總名冊!I343) -> 大陸老師 | J7: 113 | K7: A | L7: =T(總名冊!J364) -> 劉向容 | M7: =T(總名冊!I364) -> 應日一甲
B8: B | C8: =T(總名冊!J344) -> 楊 豔 | D8: =T(總名冊!I344) -> 大陸老師 | K8: B | L8: =T(總名冊!#REF!) -> #REF! | M8: =T(總名冊!I365) -> 品設一甲
B9: C | C9: =T(總名冊!J345) -> 楊 豔 | D9: =T(總名冊!I345) -> 大陸老師 | K9: C | L9: =T(總名冊!J340) -> 王淑華 | M9: =T(總名冊!I340) -> 大陸老師
A10: 87 | B10: A | C10: =T(總名冊!J346) -> 周子蘊 | D10: =T(總名冊!I346) -> 建築三甲 | J10: 115 | K10: A | L10: =T(總名冊!J367) -> 吳雨臻 | M10: =T(總名冊!I367) -> 犯防一甲
B11: B | C11: =T(總名冊!J347) -> 李維岩 | D11: =T(總名冊!I347) -> 數媒三甲 | K11: B | L11: =T(總名冊!J368) -> 李梓寧 | M11: =T(總名冊!I368) -> 犯防一乙
B12: C | C12: =T([1]退宿人員!E20) -> 李宜娟 | D12: =T([1]退宿人員!D20) -> 華教一甲 | K12: C | L12: =T(總名冊!J369) -> 黃珮柔 | M12: =T(總名冊!I369) -> 生科一甲
A13: 89 | B13: A | C13: =T(總名冊!J349) -> 陳藝丹 | D13: =T(總名冊!I349) -> 公行三甲 | J13: 117 | K13: A | L13: =T(總名冊!J370) -> 楊淯棋 | M13: =T(總名冊!I370) -> 人智二乙
B14: B | C14: =T(總名冊!J350) -> 宋佳夢 | D14: =T(總名冊!I350) -> 餐旅二甲 | K14: B | L14: =T(總名冊!J371) -> 林筱軒 | M14: =T(總名冊!I371) -> 數媒三甲
B15: C | C15: =T(總名冊!J351) -> 黃紫涵 | D15: =T(總名冊!I351) -> 商設二甲 | K15: C | L15: =T(總名冊!#REF!) -> #REF! | M15: =T(總名冊!#REF!) -> #REF!
A16: 91 | B16: A | C16: =T(總名冊!J365) -> 鄒佑姗 | D16: =T(總名冊!I352) -> 觀光三甲 | J16: 119 | K16: A | L16: =T(總名冊!J373) -> 戴宜貞 | M16: =T(總名冊!I373) -> 醫管一乙
B17: B | C17: =T(總名冊!J353) -> 邵瀟瀅 | D17: =T(總名冊!I353) -> 觀光三甲 | K17: B | L17: =T(總名冊!J374) -> 葉柔玗 | M17: =T(總名冊!I374) -> 資管四丙
B18: C | C18: =T(總名冊!J354) -> 舒靜逸 | D18: =T(總名冊!I354) -> 觀光三甲 | K18: C | L18: =T(總名冊!J375) -> 何翠華 | M18: =T(總名冊!I375) -> 資管四甲
A19: 93 | B19: A | C19: =T(總名冊!J352) -> 張怡明 | D19: =T(總名冊!I355) -> 品設二甲 | J19: 121 | K19: A | L19: =T(總名冊!J376) -> 張詠婷 | M19: =T(總名冊!I376) -> 心理三乙
B20: B | C20: =T(總名冊!J357) -> 黃雅文 | D20: =T(總名冊!I357) -> 觀光二甲 | K20: B | L20: =T(總名冊!J377) -> 黃芊穎 | M20: =T(總名冊!I377) -> 心理三甲
B21: C | C21: =T(總名冊!J355) -> 彭思桃 | D21: =T(總名冊!#REF!) -> #REF! | K21: C | L21: =T(總名冊!J378) -> 饒嘉倚 | M21: =T(總名冊!I378) -> 數媒三甲
A22: 95 | B22: A | C22: =T(總名冊!J358) -> 許以潔 | D22: =T(總名冊!I358) -> 心理二甲 | J22: 123 | K22: A | L22: =T(總名冊!J379) -> 林子琳 | M22: =T(總名冊!I379) -> 公行二甲
B23: B | C23: =T(總名冊!J359) -> 黃婷苡 | D23: =T(總名冊!I359) -> 醫工二甲 | K23: B | L23: =T(總名冊!J380) -> 陳佩沂 | M23: =T(總名冊!I380) -> 資管二甲
B24: C | C24: =T(總名冊!J360) -> 陳沛凡 | D24: =T(總名冊!I360) -> 應日二甲 | K24: C | L24: =T(總名冊!J381) -> 閔裔宸 | M24: =T(總名冊!I381) -> 資管三丙

Sheet 男生(6)
A1: 銘傳大學德明宿舍查鋪記錄表男 6F
A2: 六樓 | B2: 床號 | C2: 姓 名 | D2: 班 級 | E2: 日 | F2: 一 | G2: 二 | H2: 三 | I2: 四 | J2: 六樓 | K2: 床號 | L2: 姓 名 | M2: 班 級 | N2: 日 | O2: 一 | P2: 二 | Q2: 三 | R2: 四
A4: 97 | B4: A | C4: =T(總名冊!#REF!) -> #REF! | D4: =T(總名冊!#REF!) -> #REF! | J4: 125 | K4: A | L4: =T(總名冊!J195) -> 劉睿恩 | M4: =T(總名冊!I195) -> 商設一乙
B5: B | C5: =T(總名冊!J175) -> 邱柏睿 | D5: =T(總名冊!I175) -> 應日一乙 | K5: B | L5: =T(總名冊!J196) -> 邱友宸 | M5: =T(總名冊!I196) -> 文華一甲
B6: C | C6: =T(總名冊!J47) -> 陳信全 | D6: =T(總名冊!I47) -> 心理一乙 | K6: C | L6: =T(總名冊!J197) -> 粘松晏 | M6: =T(總名冊!I197) -> 電機一丙
A7: 99 | B7: A | C7: =T(總名冊!J177) -> 李承叡 | D7: =T(總名冊!I177) -> 心理二甲 | J7: 127 | K7: A | L7: =T(總名冊!J198) -> 林潤地 | M7: =T(總名冊!I198) -> 電機一丙
B8: B | C8: =T(總名冊!J178) -> 許哲惟 | D8: =T(總名冊!I178) -> 電機二甲 | K8: B | L8: =T(總名冊!J199) -> 賴柏豪 | M8: =T(總名冊!I199) -> 電機一甲
B9: C | C9: =T(總名冊!J179) -> 張頌恩 | D9: =T(總名冊!I179) -> 資工四乙 | K9: C | L9: =T(總名冊!J200) -> 陳冠憲 | M9: =T(總名冊!I200) -> 數媒二甲
A10: 101 | B10: A | C10: =T(總名冊!J180) -> 李祐丞 | D10: =T(總名冊!I180) -> 資工二甲 | J10: 129 | K10: A | L10: =T(總名冊!J201) -> 陳泓儒 | M10: =T(總名冊!I201) -> 醫工二甲
B11: B | C11: =T(總名冊!J181) -> 王佑鈞 | D11: =T(總名冊!I181) -> 醫管三乙 | K11: B | L11: =T(總名冊!J202) -> 曹祐瑋 | M11: =T(總名冊!I202) -> 心理二乙
B12: C | C12: =T(總名冊!J182) -> 徐家康 | D12: =T(總名冊!I182) -> 公行一甲 | K12: C | L12: =T(總名冊!J203) -> 何雋詠 | M12: =T(總名冊!I203) -> 外交學程四
A13: 103 | B13: A | C13: =T(總名冊!J183) -> 黃茂綸 | D13: =T(總名冊!I183) -> 金科一甲 | J13: 131 | K13: A | L13: =T(總名冊!J204) -> 胡恩睿 | M13: =T(總名冊!I204) -> 醫工二甲
B14: B | C14: =T(總名冊!J184) -> 陳柏樺 | D14: =T(總名冊!I184) -> 心理一乙 | K14: B | L14: =T(總名冊!J205) -> 詹少祺 | M14: =T(總名冊!I205) -> 資工二甲
B15: C | C15: =T(總名冊!J185) -> 陳俞佑 | D15: =T(總名冊!I185) -> 資工一甲 | K15: C | L15: =T(總名冊!J206) -> 莊子毅 | M15: =T(總名冊!I206) -> 電機一甲
A16: 105 | B16: A | C16: =T(總名冊!J186) -> 彭正臣 | D16: =T(總名冊!I186) -> 公行一甲 | J16: 133 | K16: A | L16: =T(總名冊!J207) -> 黃庭偉 | M16: =T(總名冊!I207) -> 電機一甲
B17: B | C17: =T(總名冊!J187) -> 黃彥璋 | D17: =T(總名冊!I187) -> 電機一乙 | K17: B | L17: =T(總名冊!J208) -> 佘承諺 | M17: =T(總名冊!I208) -> 金科一甲
B18: C | C18: =T(總名冊!J188) -> 鍾立維 | D18: =T(總名冊!I188) -> 人智三甲 | K18: C | L18: =T(總名冊!J209) -> 朱宸緯 | M18: =T(總名冊!I209) -> 人智三甲
A19: 107 | B19: A | C19: =T(總名冊!J189) -> 黎柏煇 | D19: =T(總名冊!I189) -> 休憩四甲 | J19: 135 | K19: A | L19: =T(總名冊!J210) -> 陳麒宇 | M19: =T(總名冊!I210) -> 人智三乙
B20: B | C20: =T(總名冊!J190) -> 邵証唯 | D20: =T(總名冊!I190) -> 醫工三甲 | K20: B | L20: =T(總名冊!J211) -> 鄭誌元 | M20: =T(總名冊!I211) -> 人智三甲
B21: C | C21: =T(總名冊!J191) -> 黃子豪 | D21: =T(總名冊!I191) -> 電機三丙 | K21: C | L21: =T(總名冊!J212) -> 白 崴 | M21: =T(總名冊!I212) -> 醫工二甲
A22: 109 | B22: A | C22: =T(總名冊!J192) -> 郭翔元 | D22: =T(總名冊!I192) -> 數媒四乙 | J22: 137 | K22: A | L22: =T(總名冊!J213) -> 彭昱楠 | M22: =T(總名冊!I213) -> 數媒一乙
B23: B | C23: =T(總名冊!J193) -> 李文宏 | D23: =T(總名冊!I193) -> 電機二丙 | K23: B | L23: =T(總名冊!J214) -> 吳富生 | M23: =T(總名冊!I214) -> 建築一甲
B24: C | C24: =T(總名冊!J194) -> 吳承勳 | D24: =T(總名冊!I194) -> 人智一乙 | K24: C | L24: =T(總名冊!J215) -> 黃崇恩 | M24: =T(總名冊!I215) -> 醫工二甲

Sheet 男生(7)
A1: 銘傳大學德明宿舍查鋪記錄表男 7F
A2: 七樓 | B2: 床號 | C2: 姓 名 | D2: 班 級 | E2: 日 | F2: 一 | G2: 二 | H2: 三 | I2: 四 | J2: 七樓 | K2: 床號 | L2: 姓 名 | M2: 班 級 | N2: 日 | O2: 一 | P2: 二 | Q2: 三 | R2: 四
A4: 97 | B4: A | C4: =T(總名冊!J216) -> 陳睿軒 | D4: =T(總名冊!I216) -> 醫管二甲 | J4: 125 | K4: A | L4: =T(總名冊!J237) -> 無 | M4: =T(總名冊!I237)
B5: B | C5: =T(總名冊!J217) -> 林志強 | D5: =T(總名冊!I217) -> 醫工二甲 | K5: B | L5: =T(總名冊!#REF!) -> #REF! | M5: =T(總名冊!#REF!) -> #REF!
B6: C | C6: =T(總名冊!J218) -> 達亮銜 | D6: =T(總名冊!I218) -> 數媒二甲 | K6: C | L6: =T(總名冊!J239) -> 蕭翊均 | M6: =T(總名冊!I239) -> 電機二丙
A7: 99 | B7: A | C7: =T(總名冊!J219) -> 廖俊甫 | D7: =T(總名冊!I219) -> 生科三甲 | J7: 127 | K7: A | L7: =T(總名冊!J240) -> 魏佑澄 | M7: =T(總名冊!I240) -> 犯防三乙
B8: B | C8: =T(總名冊!J220) -> 蘇晁賢 | D8: =T(總名冊!I220) -> 心理四乙 | K8: B | L8: =T(總名冊!J241) -> 徐志方 | M8: =T(總名冊!I241) -> 心理四甲
B9: C | C9: =T(總名冊!J221) -> 曾郁凱 | D9: =T(總名冊!I221) -> 資工二丙 | K9: C | L9: =T(總名冊!J242) -> 曾彥渝 | M9: =T(總名冊!I242) -> 都發一甲
A10: 101 | B10: A | C10: =T(總名冊!J222) -> 吳彥宏 | D10: =T(總名冊!I222) -> 數媒二乙 | J10: 129 | K10: A | L10: =T(總名冊!J243) -> 李家齊 | M10: =T(總名冊!I243) -> 金融一甲
B11: B | C11: =T(總名冊!J223) -> 陳泰頤 | D11: =T(總名冊!I223) -> 資工三甲 | K11: B | L11: =T(總名冊!J244) -> 簡孝存 | M11: =T(總名冊!I244) -> 都發一甲
B12: C | C12: =T(總名冊!J225) -> 陳鴻鈞 | D12: =T(總名冊!I225) -> 金融一甲 | K12: C | L12: =T(總名冊!J245) -> 黃子綱 | M12: =T(總名冊!I245) -> 資工二丙
A13: 103 | B13: A | C13: =T(總名冊!J226) -> 徐琦恩 | D13: =T(總名冊!I226) -> 金融一甲 | J13: 131 | K13: A | L13: =T(總名冊!J246) -> 曾允亮 | M13: =T(總名冊!I246) -> 人智二甲
B14: B | C14: =T(總名冊!J227) -> 曾昱愷 | D14: =T(總名冊!I227) -> 金科學程四 | K14: B | L14: =T(總名冊!J32) -> 趙宇晟 | M14: =T(總名冊!I32) -> 數媒三丁
B15: C | C15: =T(總名冊!J228) -> 徐尚恩 | D15: =T(總名冊!I228) -> 犯防三乙 | K15: C | L15: =T(總名冊!J248) -> 陳聖揚 | M15: =T(總名冊!I248) -> 外交學程二
A16: 105 | B16: A | C16: =T(總名冊!#REF!) -> #REF! | D16: =T(總名冊!#REF!) -> #REF! | J16: 133 | K16: A | L16: =T(總名冊!J249) -> 陳楚威 | M16: =T(總名冊!I249) -> 公行三甲
B17: B | C17: =T(總名冊!J229) -> 呂耕豪 | D17: =T(總名冊!I229) -> 人智二乙 | K17: B | L17: =T(總名冊!J250) -> 吳俊陞 | M17: =T(總名冊!I250) -> 數媒四丁
B18: C | C18: =T(總名冊!J230) -> 劉宇哲 | D18: =T(總名冊!I230) -> 金融一甲 | K18: C | L18: =T(總名冊!J251) -> 郭建偉 | M18: =T(總名冊!I251) -> 電機三丁
A19: 107 | B19: A | C19: =T(總名冊!J231) -> 簡群益 | D19: =T(總名冊!I231) -> 都發一甲 | J19: 135 | K19: A | L19: =T(總名冊!J252) -> 吳紹綸 | M19: =T(總名冊!I252) -> 電機三丁
B20: B | C20: =T(總名冊!J232) -> 陳俊仰 | D20: =T(總名冊!I232) -> 人智一甲 | K20: B | L20: =T(總名冊!J253) -> 連 鎧 | M20: =T(總名冊!I253) -> 金融二甲
B21: C | C21: =T(總名冊!J233) -> 無 | D21: =T(總名冊!I233) | K21: C | L21: =T(總名冊!J254) | M21: =T(總名冊!I254)
A22: 109 | B22: A | C22: =T(總名冊!J234) -> 無 | D22: =T(總名冊!I234) | J22: 137 | K22: A | L22: =T(總名冊!J255) | M22: =T(總名冊!I255)
B23: B | C23: =T(總名冊!J235) -> 無 | D23: =T(總名冊!I235) | K23: B | L23: =T(總名冊!J256) | M23: =T(總名冊!I256)
B24: C | C24: =T(總名冊!J238) -> 無 | D24: =T(總名冊!I238) | K24: C | L24: =T(總名冊!J257) | M24: =T(總名冊!I257)

Sheet 女生(1)
A1: 銘傳大學德明宿舍查鋪記錄表女 1F
A2: 一樓 | B2: 床號 | C2: 姓 名 | D2: 班 級 | E2: 日 | F2: 一 | G2: 二 | H2: 三 | I2: 四 | J2: 一樓 | K2: 床號 | L2: 姓 名 | M2: 班 級 | N2: 日 | O2: 一 | P2: 二 | Q2: 三 | R2: 四
A4: 83 | B4: A | C4: =T(總名冊!J260) | D4: =T(總名冊!I260) | J4: 113 | K4: A | L4: =T(總名冊!J281) -> 蔡聿芷 | M4: =T(總名冊!I281) -> 醫管一甲
B5: B | C5: =T(總名冊!J261) | D5: =T(總名冊!I261) | K5: B | L5: =T(總名冊!J282) -> 周家伃 | M5: =T(總名冊!I282) -> 公行四甲
B6: C | C6: =T(總名冊!#REF!) -> #REF! | D6: =T(總名冊!#REF!) -> #REF! | K6: C | L6: =T(總名冊!J283) -> 蔣忻妍 | M6: =T(總名冊!I283) -> 應日二甲
A7: 85 | B7: A | C7: =T(總名冊!#REF!) -> #REF! | D7: =T(總名冊!#REF!) -> #REF! | J7: 115 | K7: A | L7: =T(總名冊!J284) -> 楊詠晴 | M7: =T(總名冊!I284) -> 心理一乙
B8: B | C8: =T(總名冊!J264) -> 李可郁 | D8: =T(總名冊!I264) -> 資管一甲 | K8: B | L8: =T(總名冊!J285) -> 謝宜芳 | M8: =T(總名冊!I285) -> 心理四乙
B9: C | C9: =T(總名冊!J262) -> 卞思甯 | D9: =T(總名冊!I262) -> 電機二丁 | K9: C | L9: =T(總名冊!J286) -> 張舒婷 | M9: =T(總名冊!I286) -> 生科一甲
A10: 87 | B10: A | C10: =T(總名冊!J263) -> 曾湘容 | D10: =T(總名冊!I263) -> 建築一甲 | J10: 117 | K10: A | L10: =T(總名冊!J287) -> 許紫瑜 | M10: =T(總名冊!I287) -> 資工一甲
B11: B | C11: =T(總名冊!J265) -> 黃于軒 | D11: =T(總名冊!I265) -> 公行三甲 | K11: B | L11: =T(總名冊!J288) -> 何佳臻 | M11: =T(總名冊!I288) -> 數媒一甲
B12: C | C12: =T(總名冊!J268) -> 賴品竹 | D12: =T(總名冊!I268) -> 資工一乙 | K12: C | L12: =T(總名冊!J289) -> 宋怡萱 | M12: =T(總名冊!I289) -> 餐旅二甲
A13: 89 | B13: A | C13: =T(總名冊!J269) -> 魏恩惠 | D13: =T(總名冊!I269) -> 資工一甲 | J13: 119 | K13: A | L13: =T(總名冊!J290) -> 吳昀蓁 | M13: =T(總名冊!I290) -> 資管三乙
B14: B | C14: =T(總名冊!J270) -> 沈以婕 | D14: =T(總名冊!I270) -> 觀光一甲 | K14: B | L14: =T(總名冊!J291) -> 李瑋庭 | M14: =T(總名冊!I291) -> 餐旅二甲
B15: C | C15: =T(總名冊!J271) -> 蘇郅琦 | D15: =T(總名冊!I271) -> 金科學程二 | K15: C | L15: =T(總名冊!J267) -> 施愛永 | M15: =T(總名冊!I267) -> 商設三甲
A16: 91 | B16: A | C16: =T(總名冊!J272) -> 陳宣妤 | D16: =T(總名冊!I272) -> 公行三甲 | J16: 121 | K16: A | L16: =T(總名冊!J141) | M16: =T(總名冊!I141)
B17: B | C17: =T(總名冊!J273) -> 林家伃 | D17: =T(總名冊!I273) -> 醫工二甲 | K17: B | L17: =T(總名冊!#REF!) -> #REF! | M17: =T(總名冊!#REF!) -> #REF!
B18: C | C18: =T(總名冊!J372) -> 李侑芯 | D18: =T(總名冊!I372) -> 人智二乙 | K18: C | L18: =T(總名冊!J295) -> 宿管員 | M18: =T(總名冊!I295)
A19: 93 | B19: A | C19: =T(總名冊!J292) -> 健管室 | D19: =T(總名冊!I292) | J19: 123 | K19: A | L19: =T(總名冊!J2) -> 特殊 | M19: =T(總名冊!I2)
B20: B | C20: =T(總名冊!J294) -> 健管室 | D20: =T(總名冊!I294) | K20: B | L20: =T(總名冊!J3) -> 林煜晟 | M20: =T(總名冊!I3) -> 資管三甲
B21: C | C21: =T(總名冊!J277) -> 儲藏室 | D21: =T(總名冊!I277) | K21: C | L21: =T(總名冊!J4) -> 特殊 | M21: =T(總名冊!I4)
A22: 111 | B22: A | C22: =T(總名冊!J278) -> 儲藏室 | D22: =T(總名冊!I278) | J22: 125 | K22: A | L22: =T(總名冊!J5) -> 蔡承佑 | M22: =T(總名冊!I5) -> 電機三乙
B23: B | C23: =T(總名冊!J279) -> 儲藏室 | D23: =T(總名冊!I279) | K23: B | L23: =T(總名冊!J6) -> 黃晨洲 | M23: =T(總名冊!I6) -> 電機三乙
B24: C | C24: =T(總名冊!J280) -> 蔡思筠 | D24: =T(總名冊!I280) -> 商設一甲 | K24: C | L24: =T(總名冊!J7) -> 特殊 | M24: =T(總名冊!I7)

Sheet 女生(2)
A1: 銘傳大學德明宿舍查鋪記錄表女 2F
A2: 二樓 | B2: 床號 | C2: 姓 名 | D2: 班 級 | E2: 日 | F2: 一 | G2: 二 | H2: 三 | I2: 四 | J2: 二樓 | K2: 床號 | L2: 姓 名 | M2: 班 級 | N2: 日 | O2: 一 | P2: 二 | Q2: 三 | R2: 四
A4: 83 | B4: A | C4: =T(總名冊!J296) -> 宿管員 | D4: =T(總名冊!I296) | J4: 111 | K4: A | L4: =T(總名冊!J317) -> 蕭羽歆 | M4: =T(總名冊!I317) -> 心理四乙
B5: B | C5: =T(總名冊!J297) -> 宿管員 | D5: =T(總名冊!I297) | K5: B | L5: =T(總名冊!J318) -> 陳嘉敏 | M5: =T(總名冊!I318) -> 心理四甲
B6: C | C6: =T(總名冊!J298) -> 林愉廩 | D6: =T(總名冊!I298) -> 醫管一乙 | K6: C | L6: =T(總名冊!J319) -> 江亭儀 | M6: =T(總名冊!I319) -> 生科三甲
A7: 85 | B7: A | C7: =T(總名冊!J299) -> 陳慎英 | D7: =T(總名冊!I299) -> 文華一甲 | J7: 113 | K7: A | L7: =T(總名冊!J320) -> 賴姵綺 | M7: =T(總名冊!I320) -> 數媒二乙
B8: B | C8: =T(總名冊!J300) -> 吳采甯 | D8: =T(總名冊!I300) -> 犯防一乙 | K8: B | L8: =T(總名冊!J321) -> 葉家妤 | M8: =T(總名冊!I321) -> 生科三甲
B9: C | C9: =T(總名冊!J301) -> 林澄慧 | D9: =T(總名冊!I301) -> 心理四甲 | K9: C | L9: =T(總名冊!J322) -> 黃芷琳 | M9: =T(總名冊!I322) -> 數媒一甲
A10: 87 | B10: A | C10: =T(總名冊!J302) -> 曾子儀 | D10: =T(總名冊!I302) -> 心理一甲 | J10: 115 | K10: A | L10: =T(總名冊!J323) -> 蔡毓琳 | M10: =T(總名冊!I323) -> 生科四甲
B11: B | C11: =T(總名冊!J303) -> 蕭以昀 | D11: =T(總名冊!I303) -> 公行四甲 | K11: B | L11: =T(總名冊!J324) -> 吳涬妤 | M11: =T(總名冊!I324) -> 經濟四甲
B12: C | C12: =T(總名冊!J304) -> 林苡庭 | D12: =T(總名冊!I304) -> 犯防三乙 | K12: C | L12: =T(總名冊!J325) -> 劉于緁 | M12: =T(總名冊!I325) -> 資管一甲
A13: 89 | B13: A | C13: =T(總名冊!J305) -> 郭佳穎 | D13: =T(總名冊!I305) -> 犯防二乙 | J13: 117 | K13: A | L13: =T(總名冊!J326) -> 陳姸希 | M13: =T(總名冊!I326) -> 數媒一乙
B14: B | C14: =T(總名冊!J306) -> 楊芷柔 | D14: =T(總名冊!I306) -> 犯防二乙 | K14: B | L14: =T(總名冊!J329) -> 林愉庭 | M14: =T(總名冊!I329) -> 資工一丙
B15: C | C15: =T(總名冊!#REF!) -> #REF! | D15: =T(總名冊!#REF!) -> #REF! | K15: C | L15: =T(總名冊!J330) -> 王芊霖 | M15: =T(總名冊!I330) -> 金融一甲
A16: 91 | B16: A | C16: =T(總名冊!J308) -> 陳昱瑄 | D16: =T(總名冊!I308) -> 人智三乙 | J16: 119 | K16: A | L16: =T(總名冊!J331) -> 周昕霓 | M16: =T(總名冊!I331) -> 人智一甲
B17: B | C17: =T(總名冊!J309) -> 洪宥歆 | D17: =T(總名冊!I309) -> 醫管一甲 | K17: B | L17: =T(總名冊!J332) -> 賴宣妤 | M17: =T(總名冊!I332) -> 公行一甲
B18: C | C18: =T(總名冊!J310) -> 馮梓媛 | D18: =T(總名冊!I310) -> 電機三丙 | K18: C | L18: =T(總名冊!J333) -> 邱沛涵 | M18: =T(總名冊!I333) -> 資管一丙
A19: 93 | B19: A | C19: =T(總名冊!J311) -> 林宜蘋 | D19: =T(總名冊!I311) -> 電機三丙 | J19: 121 | K19: A | L19: =T(總名冊!J334) -> 洪靖恩 | M19: =T(總名冊!I334) -> 心理一甲
B20: B | C20: =T(總名冊!J312) -> 黃子晅 | D20: =T(總名冊!I312) -> 電機三丙 | K20: B | L20: =T(總名冊!J335) -> 李昀倩 | M20: =T(總名冊!I335) -> 應日一乙
B21: C | C21: =T(總名冊!J313) -> 王靖雯 | D21: =T(總名冊!I313) -> 資工四甲 | K21: C | L21: =T(總名冊!J336) -> 陳星妤 | M21: =T(總名冊!I336) -> 金融二甲
A22: 95 | B22: A | C22: =T(總名冊!J314) -> 李亭儀 | D22: =T(總名冊!I314) -> 資工四乙 | J22: 123 | K22: A | L22: =T(總名冊!J337) -> 謝汶圻 | M22: =T(總名冊!I337) -> 心理一甲
B23: B | C23: =T(總名冊!J315) -> 黃湘媛 | D23: =T(總名冊!I315) -> 資工四甲 | K23: B | L23: =T(總名冊!J338) -> 李莘渝 | M23: =T(總名冊!I338) -> 應英一甲
B24: C | C24: =T(總名冊!J316) -> 林筠青 | D24: =T(總名冊!I316) -> 資管一丙 | K24: C | L24: =T(總名冊!J339) -> 張韶妤 | M24: =T(總名冊!I339) -> 生科一乙

Sheet 女生(4)
A1: 銘傳大學德明宿舍查鋪記錄表女 4F
A2: 四樓 | B2: 床號 | C2: 姓 名 | D2: 班 級 | E2: 日 | F2: 一 | G2: 二 | H2: 三 | I2: 四 | J2: 四樓 | K2: 床號 | L2: 姓 名 | M2: 班 級 | N2: 日 | O2: 一 | P2: 二 | Q2: 三 | R2: 四
A4: 83 | B4: A | C4: =T(總名冊!J382) -> 武秋河 | D4: =T(總名冊!I382) -> 生科一丙 | J4: 111 | K4: A | L4: =T(總名冊!J403) -> 游佩蓉 | M4: =T(總名冊!I403) -> 心理二乙
B5: B | C5: =T(總名冊!J383) -> 楊郁苹 | D5: =T(總名冊!I383) -> 商設三甲 | K5: B | L5: =T(總名冊!J404) -> 何寬心 | M5: =T(總名冊!I404) -> 心理二甲
B6: C | C6: =T(總名冊!J384) -> 蘇于晴 | D6: =T(總名冊!I384) -> 統資四甲 | K6: C | L6: =T(總名冊!J405) -> 李琦淨 | M6: =T(總名冊!I405) -> 金科一甲
A7: 85 | B7: A | C7: =T(總名冊!J385) -> 神里常夏 | D7: =T(總名冊!I385) -> 觀光學程三 | J7: 113 | K7: A | L7: =T(總名冊!#REF!) -> #REF! | M7: =T(總名冊!#REF!) -> #REF!
B8: B | C8: =T(總名冊!J386) -> 網師野愛華 | D8: =T(總名冊!I386) -> 應日三甲 | K8: B | L8: =T(總名冊!#REF!) -> #REF! | M8: =T(總名冊!#REF!) -> #REF!
B9: C | C9: =T(總名冊!#REF!) -> #REF! | D9: =T(總名冊!#REF!) -> #REF! | K9: C | L9: =T(總名冊!J406) -> 蘇玟臻 | M9: =T(總名冊!I406) -> 資管三乙
A10: 87 | B10: A | C10: =T(總名冊!J388) -> 阮黎懷商 | D10: =T(總名冊!I388) -> 觀光二乙 | J10: 115 | K10: A | L10: =T(總名冊!J407) -> SOLIZ AMISHA VENESIA | M10: =T(總名冊!I407) -> 觀光學程一
B11: B | C11: =T(總名冊!J389) -> 阮氏明秋 | D11: =T(總名冊!I389) -> 觀光二乙 | K11: B | L11: =T(總名冊!#REF!) -> #REF! | M11: =T(總名冊!#REF!) -> #REF!
B12: C | C12: =T(總名冊!J390) -> 阮氏白燕 | D12: =T(總名冊!I390) -> 休憩二乙 | K12: C | L12: =T(總名冊!J409) -> THAN MAI PHUONG | M12: =T(總名冊!I409) -> 觀光學程三
A13: 89 | B13: A | C13: =T(總名冊!J391) -> 林惟眞 | D13: =T(總名冊!I391) -> 電機三甲 | J13: 117 | K13: A | L13: =T(總名冊!J410) -> NGUYEN NGOC DIEM | M13: =T(總名冊!I410) -> 觀光學程三
B14: B | C14: =T(總名冊!J392) -> 朴证仁 | D14: =T(總名冊!I392) -> 觀光學程三 | K14: B | L14: =T(總名冊!J411) -> DO DUONG MINH NGOC | M14: =T(總名冊!I411) -> 觀光學程三
B15: C | C15: =T(總名冊!J393) -> 莊詠涵 | D15: =T(總名冊!I393) -> 建築一甲 | K15: C | L15: =T(總名冊!J412) -> 范氏明恆 | M15: =T(總名冊!I412) -> 生科二丙
A16: 91 | B16: A | C16: =T(總名冊!J394) -> PHAM HONG BANG | D16: =T(總名冊!I394) -> 外交學程一 | J16: 119 | K16: A | L16: =T(總名冊!J413) -> 丁氏河妝 | M16: =T(總名冊!I413) -> 生科二丙
B17: B | C17: =T(總名冊!J395) -> 黎阮何芳 | D17: =T(總名冊!I395) -> 觀光學程四 | K17: B | L17: =T(總名冊!J414) -> 馮阮草原 | M17: =T(總名冊!I414) -> 外交學程三
B18: C | C18: =T(總名冊!J396) -> 范玉艷 | D18: =T(總名冊!I396) -> 餐旅系 | K18: C | L18: =T(總名冊!J415) -> 李昀潔 | M18: =T(總名冊!I415) -> 人智二乙
A19: 93 | B19: A | C19: =T(總名冊!J397) -> LE HA CHAU | D19: =T(總名冊!I397) -> 觀光學程三 | J19: 121 | K19: A | L19: =T(總名冊!J416) -> 盧昱蓁 | M19: =T(總名冊!I416) -> 應日三甲
B20: B | C20: =T(總名冊!J398) -> NGUYEN THU PHUONG | D20: =T(總名冊!I398) -> 觀光學程三 | K20: B | L20: =T(總名冊!J417) -> Pamela Ariel Matawan | M20: =T(總名冊!I417) -> 外交學程四
B21: C | C21: =T(總名冊!J399) -> PHAM KHANH HUYEN | D21: =T(總名冊!I399) -> 觀光學程三 | K21: C | L21: =T(總名冊!J420) -> 孫郁涵 | M21: =T(總名冊!I420) -> 應日二甲
A22: 95 | B22: A | C22: =T(總名冊!#REF!) -> #REF! | D22: =T(總名冊!#REF!) -> #REF! | J22: 123 | K22: A | L22: =T(總名冊!J421) -> 許芸瑄 | M22: =T(總名冊!I421) -> 品設一乙
B23: B | C23: =T(總名冊!J401) -> 陳宜萱 | D23: =T(總名冊!I401) -> 金融一甲 | K23: B | L23: =T(總名冊!J422) -> 林依妘 | M23: =T(總名冊!I422) -> 心理四乙
B24: C | C24: =T(總名冊!J402) -> 葉筱涵 | D24: =T(總名冊!I402) -> 餐旅一乙 | K24: C | L24: =T(總名冊!#REF!) -> #REF! | M24: =T(總名冊!#REF!) -> #REF!

Sheet 女生(5)
A1: 銘傳大學德明宿舍查鋪記錄表女 5F
A2: 五樓 | B2: 床號 | C2: 姓 名 | D2: 班 級 | E2: 日 | F2: 一 | G2: 二 | H2: 三 | I2: 四 | J2: 五樓 | K2: 床號 | L2: 姓 名 | M2: 班 級 | N2: 日 | O2: 一 | P2: 二 | Q2: 三 | R2: 四
A4: 83 | B4: A | C4: =T(總名冊!J424) | D4: =T(總名冊!I424) | J4: 111 | K4: A | L4: =T(總名冊!J445) -> 黃氏映陽 | M4: =T(總名冊!I445) -> 資工系
B5: B | C5: =T(總名冊!J425) | D5: =T(總名冊!I425) | K5: B | L5: =T(總名冊!J446) -> 賴氏玄莊 | M5: =T(總名冊!I446) -> 餐旅系
B6: C | C6: =T(總名冊!J426) | D6: =T(總名冊!I426) | K6: C | L6: =T(總名冊!J447) -> 陳嘉欣 | M6: =T(總名冊!I447) -> 觀光系
A7: 85 | B7: A | C7: =T(總名冊!J427) | D7: =T(總名冊!I427) | J7: 113 | K7: A | L7: =T(總名冊!J448) -> 阮玄妝 | M7: =T(總名冊!I448) -> 觀光系
B8: B | C8: =T(總名冊!J428) | D8: =T(總名冊!I428) | K8: B | L8: =T(總名冊!J449) -> 阮明珠 | M8: =T(總名冊!I449) -> 餐旅系
B9: C | C9: =T(總名冊!J429) | D9: =T(總名冊!I429) | K9: C | L9: =T(總名冊!J450) -> 黃氏海燕 | M9: =T(總名冊!I450) -> 餐旅系
A10: 87 | B10: A | C10: =T(總名冊!J430) -> 阮玲書 | D10: =T(總名冊!I430) -> 都發三乙 | J10: 115 | K10: A | L10: =T(總名冊!J451) -> 徐梓寧 | M10: =T(總名冊!I451) -> 公行二甲
B11: B | C11: =T(總名冊!J431) -> 梁氏蓮 | D11: =T(總名冊!I431) -> 餐旅系 | K11: B | L11: =T(總名冊!J452) -> 王英慈 | M11: =T(總名冊!I452) -> 觀光二甲
B12: C | C12: =T(總名冊!J432) -> 趙氏如 | D12: =T(總名冊!I432) -> 餐旅系 | K12: C | L12: =T(總名冊!J453) -> 葉 芃 | M12: =T(總名冊!I453) -> 品設三乙
A13: 89 | B13: A | C13: =T(總名冊!J433) -> 段氏明書 | D13: =T(總名冊!I433) -> 餐旅系 | J13: 117 | K13: A | L13: =T(總名冊!J454) -> 劉秀玟 | M13: =T(總名冊!I454) -> 人智一乙
B14: B | C14: =T(總名冊!J434) -> 陳氏玄莊 | D14: =T(總名冊!I434) -> 觀光系 | K14: B | L14: =T(總名冊!J455) -> 范姜丹辰 | M14: =T(總名冊!I455) -> 商設四乙
B15: C | C15: =T(總名冊!J435) -> 阮氏梅莊 | D15: =T(總名冊!I435) -> 觀光系 | K15: C | L15: =T(總名冊!J456) -> 陳明萱 | M15: =T(總名冊!I456) -> 商設四甲
A16: 91 | B16: A | C16: =T(總名冊!J436) -> 徐千詠 | D16: =T(總名冊!I436) -> 資管二甲 | J16: 119 | K16: A | L16: =T(總名冊!J459) -> 陳草蘭 | M16: =T(總名冊!I459) -> 觀光系
B17: B | C17: =T(總名冊!J437) -> 李之尹 | D17: =T(總名冊!I437) -> 生科二乙 | K17: B | L17: =T(總名冊!J458) -> 范氏玉簪 | M17: =T(總名冊!I458) -> 觀光系
B18: C | C18: =T(總名冊!J438) -> 莊芷妮 | D18: =T(總名冊!I438) -> 心理二乙 | K18: C | L18: =T(總名冊!J457) -> 阮氏翠姮 | M18: =T(總名冊!I457) -> 觀光系
A19: 93 | B19: A | C19: =T(總名冊!J439) -> 黃氏燕 | D19: =T(總名冊!I439) -> 餐旅系 | J19: 121 | K19: A | L19: =T(總名冊!J460) -> 張懷玲 | M19: =T(總名冊!I460) -> 觀光系
B20: B | C20: =T(總名冊!J440) -> 阮氏兒 | D20: =T(總名冊!I440) -> 餐旅系 | K20: B | L20: =T(總名冊!J461) -> 武氏玲 | M20: =T(總名冊!I461) -> 餐旅系
B21: C | C21: =T(總名冊!J441) -> 黃燕 | D21: =T(總名冊!I441) -> 餐旅系 | K21: C | L21: =T(總名冊!J462) -> 黃氏海絨 | M21: =T(總名冊!I462) -> 餐旅系
A22: 95 | B22: A | C22: =T(總名冊!J442) -> 吳珈妤 | D22: =T(總名冊!I442) -> 數媒一甲 | J22: 123 | K22: A | L22: =T(總名冊!J463) -> 黎氏玉欣 | M22: =T(總名冊!I463) -> 餐旅系
B23: B | C23: =T(總名冊!J443) -> 廖芷榆 | D23: =T(總名冊!I443) -> 電機一丙 | K23: B | L23: =T(總名冊!J464) -> 黃氏如意 | M23: =T(總名冊!I464) -> 餐旅系
B24: C | C24: =T(總名冊!J444) -> 潘奕帆 | D24: =T(總名冊!I444) -> 生科二甲 | K24: C | L24: =T(總名冊!J465) -> 范氏清姮 | M24: =T(總名冊!I465) -> 餐旅系

Sheet 女生(6)
A1: 銘傳大學德明宿舍查鋪記錄表女 6F
A2: 六樓 | B2: 床號 | C2: 姓 名 | D2: 班 級 | E2: 日 | F2: 一 | G2: 二 | H2: 三 | I2: 四 | J2: 六樓 | K2: 床號 | L2: 姓 名 | M2: 班 級 | N2: 日 | O2: 一 | P2: 二 | Q2: 三 | R2: 四
A4: 83 | B4: A | C4: =T(總名冊!J466) -> 楊雅鑫 | D4: =T(總名冊!I466) -> 電機一丙 | J4: 111 | K4: A | L4: =T(總名冊!J487) -> 廖家淇 | M4: =T(總名冊!I487) -> 醫管一乙
B5: B | C5: =T(總名冊!J467) -> 林庭伃 | D5: =T(總名冊!I467) -> 資管一丙 | K5: B | L5: =T(總名冊!J488) -> 簡立晴 | M5: =T(總名冊!I488) -> 建築四甲
B6: C | C6: =T(總名冊!J468) -> 葉紋伶 | D6: =T(總名冊!I468) -> 犯防一甲 | K6: C | L6: =T(總名冊!J489) -> 王羿涵 | M6: =T(總名冊!I489) -> 心理一甲
A7: 85 | B7: A | C7: =T(總名冊!J469) -> 陳 婧 | D7: =T(總名冊!I469) -> 犯防一甲 | J7: 113 | K7: A | L7: =T(總名冊!J490) -> 洪彤宜 | M7: =T(總名冊!I490) -> 數媒三乙
B8: B | C8: =T(總名冊!J470) -> 陳恩萱 | D8: =T(總名冊!I470) -> 餐旅二甲 | K8: B | L8: =T(總名冊!J491) -> 徐予婷 | M8: =T(總名冊!I491) -> 觀光四甲
B9: C | C9: =T(總名冊!J471) -> 謝芷芸 | D9: =T(總名冊!I471) -> 都發一甲 | K9: C | L9: =T(總名冊!J492) -> 謝淳雅 | M9: =T(總名冊!I492) -> 金融二甲
A10: 87 | B10: A | C10: =T(總名冊!J472) -> 陳嘉誼 | D10: =T(總名冊!I472) -> 外交學程一 | J10: 115 | K10: A | L10: =T(總名冊!J493) -> 劉芷妘 | M10: =T(總名冊!I493) -> 犯防一甲
B11: B | C11: =T(總名冊!#REF!) -> #REF! | D11: =T(總名冊!#REF!) -> #REF! | K11: B | L11: =T(總名冊!J494) -> 邱靖茹 | M11: =T(總名冊!I494) -> 休憩一甲
B12: C | C12: =T(總名冊!J474) -> 賴佳妤 | D12: =T(總名冊!I474) -> 公行一甲 | K12: C | L12: =T(總名冊!J495) -> 曾子芳 | M12: =T(總名冊!I495) -> 品設一乙
A13: 89 | B13: A | C13: =T(總名冊!J475) -> 吳岳音 | D13: =T(總名冊!I475) -> 數媒三甲 | J13: 117 | K13: A | L13: =T(總名冊!J496) -> 許昱涵 | M13: =T(總名冊!I496) -> 金融二甲
B14: B | C14: =T(總名冊!J476) -> 張芷熏 | D14: =T(總名冊!I476) -> 數媒三甲 | K14: B | L14: =T(總名冊!J497) -> 葉宣妤 | M14: =T(總名冊!I497) -> 電機三乙
B15: C | C15: =T(總名冊!J477) -> 邱梓芸 | D15: =T(總名冊!I477) -> 數媒三甲 | K15: C | L15: =T(總名冊!J400) -> 丁燕玲 | M15: =T(總名冊!I400) -> 生科二丙
A16: 91 | B16: A | C16: =T(總名冊!J478) -> 謝孟琪 | D16: =T(總名冊!I478) -> 心理一甲 | J16: 119 | K16: A | L16: =T(總名冊!J503) -> 趙晨妤 | M16: =T(總名冊!I503) -> 醫工一甲
B17: B | C17: =T(總名冊!J423) -> 魏伊羚 | D17: =T(總名冊!I423) -> 資工一甲 | K17: B | L17: =T(總名冊!J500) -> 謝渝淇 | M17: =T(總名冊!I500) -> 資工一甲
B18: C | C18: =T(總名冊!J480) -> 洪瑋赯 | D18: =T(總名冊!I480) -> 應日三甲 | K18: C | L18: =T(總名冊!J501) -> 羅元婍 | M18: =T(總名冊!I501) -> 品設一乙
A19: 93 | B19: A | C19: =T(總名冊!J481) -> 許百惠 | D19: =T(總名冊!I481) -> 心理四乙 | J19: 121 | K19: A | L19: =T(總名冊!J502) -> 蔡沁予 | M19: =T(總名冊!I502) -> 生科一甲
B20: B | C20: =T(總名冊!J482) -> 陳思澐 | D20: =T(總名冊!I482) -> 電機四甲 | K20: B | L20: =T(總名冊!#REF!) -> #REF! | M20: =T(總名冊!#REF!) -> #REF!
B21: C | C21: =T(總名冊!J483) -> 曾衣琁 | D21: =T(總名冊!I483) -> 商設四甲 | K21: C | L21: =T(總名冊!J504) -> 鄭嫄薺 | M21: =T(總名冊!I504) -> 人智四甲
A22: 95 | B22: A | C22: =T(總名冊!J484) -> 顧善美 | D22: =T(總名冊!I484) -> 資工三甲 | J22: 123 | K22: A | L22: =T(總名冊!#REF!) -> #REF! | M22: =T(總名冊!#REF!) -> #REF!
B23: B | C23: =T(總名冊!J485) -> 賴姿妤 | D23: =T(總名冊!I485) -> 商設三甲 | K23: B | L23: =T(總名冊!#REF!) -> #REF! | M23: =T(總名冊!#REF!) -> #REF!
B24: C | C24: =T(總名冊!J486) -> 吳旻恩 | D24: =T(總名冊!I486) -> 觀光四甲 | K24: C | L24: =T(總名冊!J505) -> 楊旻芯 | M24: =T(總名冊!I505) -> 資管三乙

Sheet 女生(7)
A1: 銘傳大學德明宿舍查鋪記錄表女 7F
A2: 六樓 | B2: 床號 | C2: 姓 名 | D2: 班 級 | E2: 日 | F2: 一 | G2: 二 | H2: 三 | I2: 四 | J2: 六樓 | K2: 床號 | L2: 姓 名 | M2: 班 級 | N2: 日 | O2: 一 | P2: 二 | Q2: 三 | R2: 四
A4: 83 | B4: A | C4: =T(總名冊!J506) -> 葉羿彣 | D4: =T(總名冊!I506) -> 應日二甲 | J4: 111 | K4: A | L4: =T(總名冊!#REF!) -> #REF! | M4: =T(總名冊!#REF!) -> #REF!
B5: B | C5: =T(總名冊!J507) -> 陳彥菱 | D5: =T(總名冊!I507) -> 應日二甲 | K5: B | L5: =T(總名冊!#REF!) -> #REF! | M5: =T(總名冊!#REF!) -> #REF!
B6: C | C6: =T(總名冊!J508) | D6: =T(總名冊!I508) | K6: C | L6: =T(總名冊!J529) | M6: =T(總名冊!I529)
A7: 85 | B7: A | C7: =T(總名冊!J509) | D7: =T(總名冊!I509) | J7: 113 | K7: A | L7: =T(總名冊!J530) | M7: =T(總名冊!I530)
B8: B | C8: =T(總名冊!J510) | D8: =T(總名冊!I510) | K8: B | L8: =T(總名冊!#REF!) -> #REF! | M8: =T(總名冊!#REF!) -> #REF!
B9: C | C9: =T(總名冊!J511) -> 方怡媃 | D9: =T(總名冊!I511) -> 商設一甲 | K9: C | L9: =T(總名冊!J527) -> 劉珮慈 | M9: =T(總名冊!I527) -> 心理四甲
A10: 87 | B10: A | C10: =T(總名冊!J512) -> 邱于甄 | D10: =T(總名冊!I512) -> 醫工一甲 | J10: 115 | K10: A | L10: =T(總名冊!J533) -> 孫傑臻 | M10: =T(總名冊!I533) -> 文華一甲
B11: B | C11: =T(總名冊!J513) -> 杜淓穎 | D11: =T(總名冊!I513) -> 商設一乙 | K11: B | L11: =T(總名冊!J534) -> 江書侑 | M11: =T(總名冊!I534) -> 品設一甲
B12: C | C12: =T(總名冊!J521) -> 陳依綺 | D12: =T(總名冊!I521) -> 資管三甲 | K12: C | L12: =T(總名冊!J535) -> 鄭維庭 | M12: =T(總名冊!I535) -> 商設三乙
A13: 89 | B13: A | C13: =T(總名冊!J515) -> 吳依恩 | D13: =T(總名冊!I515) -> 餐旅二甲 | J13: 117 | K13: A | L13: =T(總名冊!J536) -> 何有容 | M13: =T(總名冊!I536) -> 商設四甲
B14: B | C14: =T(總名冊!J516) -> 陳渝柔 | D14: =T(總名冊!I516) -> 品設一乙 | K14: B | L14: =T(總名冊!J537) -> 張瑋庭 | M14: =T(總名冊!I537) -> 建築三甲
B15: C | C15: =T(總名冊!J517) -> 黃婉翎 | D15: =T(總名冊!I517) -> 品設一乙 | K15: C | L15: =T(總名冊!J538) -> 林樂晴 | M15: =T(總名冊!I538) -> 犯防一乙
A16: 91 | B16: A | C16: =T(總名冊!J518) -> 羅苡菱 | D16: =T(總名冊!I518) -> 資工一甲 | J16: 119 | K16: A | L16: =T(總名冊!J539) -> 陳儀恩 | M16: =T(總名冊!I539) -> 公行一甲
B17: B | C17: =T(總名冊!J519) -> 鄭聿喬 | D17: =T(總名冊!I519) -> 犯防一乙 | K17: B | L17: =T(總名冊!J540) -> 施忞萱 | M17: =T(總名冊!I540) -> 資管一乙
B18: C | C18: =T(總名冊!J520) -> 楊雅婷 | D18: =T(總名冊!I520) -> 統資四甲 | K18: C | L18: =T(總名冊!J541) -> 游妤庭 | M18: =T(總名冊!I541) -> 商設四甲
A19: 93 | B19: A | C19: =T(總名冊!#REF!) -> #REF! | D19: =T(總名冊!#REF!) -> #REF! | J19: 121 | K19: A | L19: =T(總名冊!J542) -> 邱羽芹 | M19: =T(總名冊!I542) -> 金科一甲
B20: B | C20: =T(總名冊!J522) -> 姚雅涵 | D20: =T(總名冊!I522) -> 統資四甲 | K20: B | L20: =T(總名冊!J543) -> 楊捷媃 | M20: =T(總名冊!I543) -> 電機一丙
B21: C | C21: =T(總名冊!J523) -> 趙翊廷 | D21: =T(總名冊!I523) -> 醫管三乙 | K21: C | L21: =T(總名冊!J544) -> 柳岑樺 | M21: =T(總名冊!I544) -> 生科二乙
A22: 95 | B22: A | C22: =T(總名冊!J524) -> 侯淯宸 | D22: =T(總名冊!I524) -> 醫工三甲 | J22: 123 | K22: A | L22: =T(總名冊!J545) -> 邱靖媗 | M22: =T(總名冊!I545) -> 犯防二乙
B23: B | C23: =T(總名冊!J525) -> 古羽庭 | D23: =T(總名冊!I525) -> 電機三甲 | K23: B | L23: =T(總名冊!J546) -> 郭子瑄 | M23: =T(總名冊!I546) -> 犯防二乙
B24: C | C24: =T(總名冊!J528) -> 秦子涵 | D24: =T(總名冊!I528) -> 休憩四甲 | K24: C | L24: =T(總名冊!J547) -> 林靖軒 | M24: =T(總名冊!I547) -> 品設二甲
